test_build_recursive_sequence_generator (__main__.TestExercice.test_build_recursive_sequence_generator) ... FAIL
test_fibonacci_number (__main__.TestExercice.test_fibonacci_number) ... ERROR
test_get_fibonacci_number (__main__.TestExercice.test_get_fibonacci_number) ... ok
test_get_fibonacci_sequence (__main__.TestExercice.test_get_fibonacci_sequence) ... FAIL
test_get_sorted_dict_by_decimals (__main__.TestExercice.test_get_sorted_dict_by_decimals) ... ok

======================================================================
ERROR: test_fibonacci_number (__main__.TestExercice.test_fibonacci_number)
----------------------------------------------------------------------
Traceback (most recent call last):
  File "d:\Semestre 1\INF1007\chapitre-07-2-AndLpt\test_exercice.py", line 69, in test_fibonacci_number
    output = [fibo for fibo in fibonacci_numbers(10)]
             ^^^^^^^^^^^^^^^^^^^^^^^^^^^^^^^^^^^^^^^^
TypeError: 'NoneType' object is not iterable

======================================================================
FAIL: test_build_recursive_sequence_generator (__main__.TestExercice.test_build_recursive_sequence_generator)
----------------------------------------------------------------------
Traceback (most recent call last):
  File "d:\Semestre 1\INF1007\chapitre-07-2-AndLpt\test_exercice.py", line 80, in test_build_recursive_sequence_generator
    fibo = build_recursive_sequence_generator([0, 1], fibo_def, False)
           ^^^^^^^^^^^^^^^^^^^^^^^^^^^^^^^^^^^^^^^^^^^^^^^^^^^^^^^^^^^
TypeError: build_recursive_sequence_generator() takes 1 positional argument but 3 were given

During handling of the above exception, another exception occurred:

Traceback (most recent call last):
  File "d:\Semestre 1\INF1007\chapitre-07-2-AndLpt\test_exercice.py", line 82, in test_build_recursive_sequence_generator
    self.fail("l'appel échoue")
AssertionError: l'appel échoue

======================================================================
FAIL: test_get_fibonacci_sequence (__main__.TestExercice.test_get_fibonacci_sequence)
----------------------------------------------------------------------
Traceback (most recent call last):
  File "d:\Semestre 1\INF1007\chapitre-07-2-AndLpt\test_exercice.py", line 36, in test_get_fibonacci_sequence
    self.assertListEqual(
AssertionError: Lists differ: [[<generator object get_fibonacci_sequence.[1436 chars]20>]] != [[0], [0, 1], [0, 1, 1, 2, 3], [0, 1, 1, 2,[17 chars] 34]]

First differing element 0:
[<generator object get_fibonacci_sequence.[35 chars]E60>]
[0]

Diff is 1620 characters long. Set self.maxDiff to None to see it.

----------------------------------------------------------------------
Ran 5 tests in 0.005s

FAILED (failures=2, errors=1)
